<?xml version="1.0" ?>
<robot name="go1_description" xmlns:xacro="http://www.ros.org/wiki/xacro">
  <material name="black">
    <color rgba="0.0 0.0 0.0 1.0"/>
  </material>
  <material name="blue">
    <color rgba="0.0 0.0 0.8 1.0"/>
  </material>
  <material name="green">
    <color rgba="0.0 0.8 0.0 1.0"/>
  </material>
  <material name="grey">
    <color rgba="0.2 0.2 0.2 1.0"/>
  </material>
  <material name="silver">
    <color rgba="0.913725490196 0.913725490196 0.847058823529 1.0"/>
  </material>
  <material name="orange">
    <color rgba="1.0 0.423529411765 0.0392156862745 1.0"/>
  </material>
  <material name="brown">
    <color rgba="0.870588235294 0.811764705882 0.764705882353 1.0"/>
  </material>
  <material name="red">
    <color rgba="0.8 0.0 0.0 1.0"/>
  </material>
  <material name="white">
    <color rgba="1.0 1.0 1.0 1.0"/>
  </material>


  <link name="base">
    <visual>
      <origin rpy="0 0 0" xyz="0 0 0"/>
      <geometry>
        <box size="0.001 0.001 0.001"/>
      </geometry>
    </visual>
  </link>
  <joint name="floating_base" type="fixed">
    <origin rpy="0 0 0" xyz="0 0 0"/>
    <parent link="base"/>
    <child link="trunk"/>
  </joint>
  <link name="trunk">
    <visual>
      <origin rpy="0 0 0" xyz="0 0 0"/>
      <geometry>
        <mesh filename="../meshes/trunk.stl" scale="1 1 1"/>
      </geometry>
      <material name="silver"/>
    </visual>
    <collision>
      <origin rpy="0 0 0" xyz="0 0 0"/>
      <geometry>
        <box size="0.3762 0.0935 0.114"/>
      </geometry>
    </collision>
    <inertial>
      <origin rpy="0 0 0" xyz="0.011611 0.004437 0.000108"/>
      <mass value="4.8"/>
      <inertia ixx="0.016130741919" ixy="0.000593180607" ixz="7.324662e-06" iyy="0.036507810812" iyz="2.0969537e-05" izz="0.044693872053"/>
    </inertial>
  </link>
  <joint name="imu_joint" type="fixed">
    <parent link="trunk"/>
    <child link="imu_link"/>
    <origin rpy="0 0 0" xyz="-0.01592 -0.06659 -0.00617"/>
  </joint>
  <link name="imu_link">
    <inertial>
      <mass value="0.001"/>
      <origin rpy="0 0 0" xyz="0 0 0"/>
      <inertia ixx="0.0001" ixy="0" ixz="0" iyy="0.0001" iyz="0" izz="0.0001"/>
    </inertial>
    <visual>
      <origin rpy="0 0 0" xyz="0 0 0"/>
      <geometry>
        <box size="0.001 0.001 0.001"/>
      </geometry>
      <material name="red"/>
    </visual>
    <collision>
      <origin rpy="0 0 0" xyz="0 0 0"/>
      <geometry>
        <box size=".001 .001 .001"/>
      </geometry>
    </collision>
  </link>
  <joint name="FR_hip_joint" type="revolute">
    <origin rpy="0 0 0" xyz="0.1881 -0.04675 0"/>
    <parent link="trunk"/>
    <child link="FR_hip"/>
    <axis xyz="1 0 0"/>
    <dynamics damping="0" friction="0"/>
    <limit effort="33.5" lower="-0.802851455917" upper="0.802851455917" velocity="50"/>
  </joint>
  <link name="FR_hip">
    <visual>
      <origin rpy="3.14159265359 0 0" xyz="0 0 0"/>
      <geometry>
        <mesh filename="../meshes/hip.stl" scale="1 1 1"/>
      </geometry>
      <material name="silver"/>
    </visual>
    <collision>
      <origin rpy="1.57079632679 0 0" xyz="0 -0.045 0"/>
      <geometry>
        <cylinder length="0.04" radius="0.046"/>
      </geometry>
    </collision>
    <inertial>
      <origin rpy="0 0 0" xyz="-0.00541 0.00074 6e-06"/>
      <mass value="0.510299"/>
      <inertia ixx="0.00030528937" ixy="7.788013e-06" ixz="2.2016e-07" iyy="0.000590894859" iyz="1.7175e-08" izz="0.000396594572"/>
    </inertial>
  </link>
  <joint name="FR_hip_fixed" type="fixed">
    <origin rpy="0 0 0" xyz="0 -0.08 0"/>
    <parent link="FR_hip"/>
    <child link="FR_thigh_shoulder"/>
  </joint>
  <!-- this link is only for collision -->
  <link name="FR_thigh_shoulder">
    <collision>
      <origin rpy="1.57079632679 0 0" xyz="0 0 0"/>
      <geometry>
        <cylinder length="0.032" radius="0.041"/>
      </geometry>
    </collision>
  </link>
  <joint name="FR_thigh_joint" type="revolute">
    <origin rpy="0 0 0" xyz="0 -0.08 0"/>
    <parent link="FR_hip"/>
    <child link="FR_thigh"/>
    <axis xyz="0 1 0"/>
    <dynamics damping="0" friction="0"/>
    <limit effort="33.5" lower="-1.0471975512" upper="4.18879020479" velocity="28"/>
  </joint>
  <link name="FR_thigh">
    <visual>
      <origin rpy="0 0 0" xyz="0 0 0"/>
      <geometry>
        <mesh filename="../meshes/thigh_mirror.stl" scale="1 1 1"/>
      </geometry>
      <material name="silver"/>
    </visual>
    <collision>
      <origin rpy="0 1.57079632679 0" xyz="0 0 -0.1065"/>
      <geometry>
        <box size="0.213 0.0245 0.034"/>
      </geometry>
    </collision>
    <inertial>
      <origin rpy="0 0 0" xyz="-0.003468 0.018947 -0.032736"/>
      <mass value="0.898919"/>
      <inertia ixx="0.005395867678" ixy="-1.02809e-07" ixz="0.000337529085" iyy="0.005142451046" iyz="5.816563e-06" izz="0.00102478732"/>
    </inertial>
  </link>
  <joint name="FR_calf_joint" type="revolute">
    <origin rpy="0 0 0" xyz="0 0 -0.213"/>
    <parent link="FR_thigh"/>
    <child link="FR_calf"/>
    <axis xyz="0 1 0"/>
    <dynamics damping="0" friction="0"/>
    <limit effort="33.5" lower="-2.69653369433" upper="-0.916297857297" velocity="28"/>
  </joint>
  <link name="FR_calf">
    <visual>
      <origin rpy="0 0 0" xyz="0 0 0"/>
      <geometry>
        <mesh filename="../meshes/calf.stl" scale="1 1 1"/>
      </geometry>
      <material name="black"/>
    </visual>
    <collision>
      <origin rpy="0 1.57079632679 0" xyz="0 0 -0.1065"/>
      <geometry>
        <box size="0.213 0.016 0.016"/>
      </geometry>
    </collision>
    <inertial>
      <origin rpy="0 0 0" xyz="0.006286 0.001307 -0.122269"/>
      <mass value="0.158015"/>
      <inertia ixx="0.003607648222" ixy="1.494971e-06" ixz="-0.000132778525" iyy="0.003626771492" iyz="-2.8638535e-05" izz="3.5148003e-05"/>
    </inertial>
  </link>
  <joint name="FR_foot_fixed" type="fixed" dont_collapse="true">
    <origin rpy="0 0 0" xyz="0 0 -0.213"/>
    <parent link="FR_calf"/>
    <child link="FR_foot"/>
  </joint>
  <link name="FR_foot">
    <visual>
      <origin rpy="0 0 0" xyz="0 0 0"/>
      <geometry>
        <sphere radius="0.01"/>
      </geometry>
      <material name="black"/>
    </visual>
    <collision>
      <origin rpy="0 0 0" xyz="0 0 0"/>
      <geometry>
        <sphere radius="0.02"/>
      </geometry>
    </collision>
    <inertial>
      <mass value="0.06"/>
      <inertia ixx="9.6e-06" ixy="0.0" ixz="0.0" iyy="9.6e-06" iyz="0.0" izz="9.6e-06"/>
    </inertial>
  </link>

  <joint name="FL_hip_joint" type="revolute">
    <origin rpy="0 0 0" xyz="0.1881 0.04675 0"/>
    <parent link="trunk"/>
    <child link="FL_hip"/>
    <axis xyz="1 0 0"/>
    <dynamics damping="0" friction="0"/>
    <limit effort="33.5" lower="-0.802851455917" upper="0.802851455917" velocity="50"/>
  </joint>
  <link name="FL_hip">
    <visual>
      <origin rpy="0 0 0" xyz="0 0 0"/>
      <geometry>
        <mesh filename="../meshes/hip.stl" scale="1 1 1"/>
      </geometry>
      <material name="silver"/>
    </visual>
    <collision>
      <origin rpy="1.57079632679 0 0" xyz="0 0.045 0"/>
      <geometry>
        <cylinder length="0.04" radius="0.046"/>
      </geometry>
    </collision>
    <inertial>
      <origin rpy="0 0 0" xyz="-0.00541 -0.00074 6e-06"/>
      <mass value="0.510299"/>
      <inertia ixx="0.00030528937" ixy="-7.788013e-06" ixz="2.2016e-07" iyy="0.000590894859" iyz="-1.7175e-08" izz="0.000396594572"/>
    </inertial>
  </link>
  <joint name="FL_hip_fixed" type="fixed">
    <origin rpy="0 0 0" xyz="0 0.08 0"/>
    <parent link="FL_hip"/>
    <child link="FL_thigh_shoulder"/>
  </joint>
  <!-- this link is only for collision -->
  <link name="FL_thigh_shoulder">
    <collision>
      <origin rpy="1.57079632679 0 0" xyz="0 0 0"/>
      <geometry>
        <cylinder length="0.032" radius="0.041"/>
      </geometry>
    </collision> 
  </link>
  <joint name="FL_thigh_joint" type="revolute">
    <origin rpy="0 0 0" xyz="0 0.08 0"/>
    <parent link="FL_hip"/>
    <child link="FL_thigh"/>
    <axis xyz="0 1 0"/>
    <dynamics damping="0" friction="0"/>
    <limit effort="33.5" lower="-1.0471975512" upper="4.18879020479" velocity="28"/>
  </joint>
  <link name="FL_thigh">
    <visual>
      <origin rpy="0 0 0" xyz="0 0 0"/>
      <geometry>
        <mesh filename="../meshes/thigh.stl" scale="1 1 1"/>
      </geometry>
      <material name="silver"/>
    </visual>
    <collision>
      <origin rpy="0 1.57079632679 0" xyz="0 0 -0.1065"/>
      <geometry>
        <box size="0.213 0.0245 0.034"/>
      </geometry>
    </collision>
    <inertial>
      <origin rpy="0 0 0" xyz="-0.003468 -0.018947 -0.032736"/>
      <mass value="0.898919"/>
      <inertia ixx="0.005395867678" ixy="1.02809e-07" ixz="0.000337529085" iyy="0.005142451046" iyz="-5.816563e-06" izz="0.00102478732"/>
    </inertial>
  </link>
  <joint name="FL_calf_joint" type="revolute">
    <origin rpy="0 0 0" xyz="0 0 -0.213"/>
    <parent link="FL_thigh"/>
    <child link="FL_calf"/>
    <axis xyz="0 1 0"/>
    <dynamics damping="0" friction="0"/>
    <limit effort="33.5" lower="-2.69653369433" upper="-0.916297857297" velocity="28"/>
  </joint>
  <link name="FL_calf">
    <visual>
      <origin rpy="0 0 0" xyz="0 0 0"/>
      <geometry>
        <mesh filename="../meshes/calf.stl" scale="1 1 1"/>
      </geometry>
      <material name="silver"/>
    </visual>
    <collision>
      <origin rpy="0 1.57079632679 0" xyz="0 0 -0.1065"/>
      <geometry>
        <box size="0.213 0.016 0.016"/>
      </geometry>
    </collision>
    <inertial>
      <origin rpy="0 0 0" xyz="0.006286 0.001307 -0.122269"/>
      <mass value="0.158015"/>
      <inertia ixx="0.003607648222" ixy="1.494971e-06" ixz="-0.000132778525" iyy="0.003626771492" iyz="-2.8638535e-05" izz="3.5148003e-05"/>
    </inertial>
  </link>
  <joint name="FL_foot_fixed" type="fixed" dont_collapse="true">
    <origin rpy="0 0 0" xyz="0 0 -0.213"/>
    <parent link="FL_calf"/>
    <child link="FL_foot"/>
  </joint>
  <link name="FL_foot">
    <visual>
      <origin rpy="0 0 0" xyz="0 0 0"/>
      <geometry>
        <sphere radius="0.01"/>
      </geometry>
      <material name="black"/>
    </visual>
    <collision>
      <origin rpy="0 0 0" xyz="0 0 0"/>
      <geometry>
        <sphere radius="0.02"/>
      </geometry>
    </collision>
    <inertial>
      <mass value="0.06"/>
      <inertia ixx="9.6e-06" ixy="0.0" ixz="0.0" iyy="9.6e-06" iyz="0.0" izz="9.6e-06"/>
    </inertial>
  </link>

  <joint name="RR_hip_joint" type="revolute">
    <origin rpy="0 0 0" xyz="-0.1881 -0.04675 0"/>
    <parent link="trunk"/>
    <child link="RR_hip"/>
    <axis xyz="1 0 0"/>
    <dynamics damping="0" friction="0"/>
    <limit effort="33.5" lower="-0.802851455917" upper="0.802851455917" velocity="50"/>
  </joint>
  <link name="RR_hip">
    <visual>
      <origin rpy="3.14159265359 3.14159265359 0" xyz="0 0 0"/>
      <geometry>
        <mesh filename="../meshes/hip.stl" scale="1 1 1"/>
      </geometry>
      <material name="silver"/>
    </visual>
    <collision>
      <origin rpy="1.57079632679 0 0" xyz="0 -0.045 0"/>
      <geometry>
        <cylinder length="0.04" radius="0.046"/>
      </geometry>
    </collision>
    <inertial>
      <origin rpy="0 0 0" xyz="0.00541 0.00074 6e-06"/>
      <mass value="0.510299"/>
      <inertia ixx="0.00030528937" ixy="-7.788013e-06" ixz="-2.2016e-07" iyy="0.000590894859" iyz="1.7175e-08" izz="0.000396594572"/>
    </inertial>
  </link>
  <joint name="RR_hip_fixed" type="fixed">
    <origin rpy="0 0 0" xyz="0 -0.08 0"/>
    <parent link="RR_hip"/>
    <child link="RR_thigh_shoulder"/>
  </joint>
  <!-- this link is only for collision -->
  <link name="RR_thigh_shoulder">
    <collision>
      <origin rpy="1.57079632679 0 0" xyz="0 0 0"/>
      <geometry>
        <cylinder length="0.032" radius="0.041"/>
      </geometry>
    </collision>
  </link>
  <joint name="RR_thigh_joint" type="revolute">
    <origin rpy="0 0 0" xyz="0 -0.08 0"/>
    <parent link="RR_hip"/>
    <child link="RR_thigh"/>
    <axis xyz="0 1 0"/>
    <dynamics damping="0" friction="0"/>
    <limit effort="33.5" lower="-1.0471975512" upper="4.18879020479" velocity="28"/>
  </joint>
  <link name="RR_thigh">
    <visual>
      <origin rpy="0 0 0" xyz="0 0 0"/>
      <geometry>
        <mesh filename="../meshes/thigh_mirror.stl" scale="1 1 1"/>
      </geometry>
      <material name="silver"/>
    </visual>
    <collision>
      <origin rpy="0 1.57079632679 0" xyz="0 0 -0.1065"/>
      <geometry>
        <box size="0.213 0.0245 0.034"/>
      </geometry>
    </collision>
    <inertial>
      <origin rpy="0 0 0" xyz="-0.003468 0.018947 -0.032736"/>
      <mass value="0.898919"/>
      <inertia ixx="0.005395867678" ixy="-1.02809e-07" ixz="0.000337529085" iyy="0.005142451046" iyz="5.816563e-06" izz="0.00102478732"/>
    </inertial>
  </link>
  <joint name="RR_calf_joint" type="revolute">
    <origin rpy="0 0 0" xyz="0 0 -0.213"/>
    <parent link="RR_thigh"/>
    <child link="RR_calf"/>
    <axis xyz="0 1 0"/>
    <dynamics damping="0" friction="0"/>
    <limit effort="33.5" lower="-2.69653369433" upper="-0.916297857297" velocity="28"/>
  </joint>
  <link name="RR_calf">
    <visual>
      <origin rpy="0 0 0" xyz="0 0 0"/>
      <geometry>
        <mesh filename="../meshes/calf.stl" scale="1 1 1"/>
      </geometry>
      <material name="black"/>
    </visual>
    <collision>
      <origin rpy="0 1.57079632679 0" xyz="0 0 -0.1065"/>
      <geometry>
        <box size="0.213 0.016 0.016"/>
      </geometry>
    </collision>
    <inertial>
      <origin rpy="0 0 0" xyz="0.006286 0.001307 -0.122269"/>
      <mass value="0.158015"/>
      <inertia ixx="0.003607648222" ixy="1.494971e-06" ixz="-0.000132778525" iyy="0.003626771492" iyz="-2.8638535e-05" izz="3.5148003e-05"/>
    </inertial>
  </link>
  <joint name="RR_foot_fixed" type="fixed" dont_collapse="true">
    <origin rpy="0 0 0" xyz="0 0 -0.213"/>
    <parent link="RR_calf"/>
    <child link="RR_foot"/>
  </joint>
  <link name="RR_foot">
    <visual>
      <origin rpy="0 0 0" xyz="0 0 0"/>
      <geometry>
        <sphere radius="0.01"/>
      </geometry>
      <material name="black"/>
    </visual>
    <collision>
      <origin rpy="0 0 0" xyz="0 0 0"/>
      <geometry>
        <sphere radius="0.02"/>
      </geometry>
    </collision>
    <inertial>
      <mass value="0.06"/>
      <inertia ixx="9.6e-06" ixy="0.0" ixz="0.0" iyy="9.6e-06" iyz="0.0" izz="9.6e-06"/>
    </inertial>
  </link>

  <joint name="RL_hip_joint" type="revolute">
    <origin rpy="0 0 0" xyz="-0.1881 0.04675 0"/>
    <parent link="trunk"/>
    <child link="RL_hip"/>
    <axis xyz="1 0 0"/>
    <dynamics damping="0" friction="0"/>
    <limit effort="33.5" lower="-0.802851455917" upper="0.802851455917" velocity="50"/>
  </joint>
  <link name="RL_hip">
    <visual>
      <origin rpy="0 3.14159265359 0" xyz="0 0 0"/>
      <geometry>
        <mesh filename="../meshes/hip.stl" scale="1 1 1"/>
      </geometry>
      <material name="silver"/>
    </visual>
    <collision>
      <origin rpy="1.57079632679 0 0" xyz="0 0.045 0"/>
      <geometry>
        <cylinder length="0.04" radius="0.046"/>
      </geometry>
    </collision>
    <inertial>
      <origin rpy="0 0 0" xyz="0.00541 -0.00074 6e-06"/>
      <mass value="0.510299"/>
      <inertia ixx="0.00030528937" ixy="7.788013e-06" ixz="-2.2016e-07" iyy="0.000590894859" iyz="-1.7175e-08" izz="0.000396594572"/>
    </inertial>
  </link>
  <joint name="RL_hip_fixed" type="fixed">
    <origin rpy="0 0 0" xyz="0 0.08 0"/>
    <parent link="RL_hip"/>
    <child link="RL_thigh_shoulder"/>
  </joint>
  <!-- this link is only for collision -->
  <link name="RL_thigh_shoulder">
    <collision>
      <origin rpy="1.57079632679 0 0" xyz="0 0 0"/>
      <geometry>
        <cylinder length="0.032" radius="0.041"/>
      </geometry>
    </collision>
  </link>
  <joint name="RL_thigh_joint" type="revolute">
    <origin rpy="0 0 0" xyz="0 0.08 0"/>
    <parent link="RL_hip"/>
    <child link="RL_thigh"/>
    <axis xyz="0 1 0"/>
    <dynamics damping="0" friction="0"/>
    <limit effort="33.5" lower="-1.0471975512" upper="4.18879020479" velocity="28"/>
  </joint>
  <link name="RL_thigh">
    <visual>
      <origin rpy="0 0 0" xyz="0 0 0"/>
      <geometry>
        <mesh filename="../meshes/thigh.stl" scale="1 1 1"/>
      </geometry>
      <material name="silver"/>
    </visual>
    <collision>
      <origin rpy="0 1.57079632679 0" xyz="0 0 -0.1065"/>
      <geometry>
        <box size="0.213 0.0245 0.034"/>
      </geometry>
    </collision>
    <inertial>
      <origin rpy="0 0 0" xyz="-0.003468 -0.018947 -0.032736"/>
      <mass value="0.898919"/>
      <inertia ixx="0.005395867678" ixy="1.02809e-07" ixz="0.000337529085" iyy="0.005142451046" iyz="-5.816563e-06" izz="0.00102478732"/>
    </inertial>
  </link>
  <joint name="RL_calf_joint" type="revolute">
    <origin rpy="0 0 0" xyz="0 0 -0.213"/>
    <parent link="RL_thigh"/>
    <child link="RL_calf"/>
    <axis xyz="0 1 0"/>
    <dynamics damping="0" friction="0"/>
    <limit effort="33.5" lower="-2.69653369433" upper="-0.916297857297" velocity="28"/>
  </joint>
  <link name="RL_calf">
    <visual>
      <origin rpy="0 0 0" xyz="0 0 0"/>
      <geometry>
        <mesh filename="../meshes/calf.stl" scale="1 1 1"/>
      </geometry>
      <material name="black"/>
    </visual>
    <collision>
      <origin rpy="0 1.57079632679 0" xyz="0 0 -0.1065"/>
      <geometry>
        <box size="0.213 0.016 0.016"/>
      </geometry>
    </collision>
    <inertial>
      <origin rpy="0 0 0" xyz="0.006286 0.001307 -0.122269"/>
      <mass value="0.158015"/>
      <inertia ixx="0.003607648222" ixy="1.494971e-06" ixz="-0.000132778525" iyy="0.003626771492" iyz="-2.8638535e-05" izz="3.5148003e-05"/>
    </inertial>
  </link>
  <joint name="RL_foot_fixed" type="fixed" dont_collapse="true">
    <origin rpy="0 0 0" xyz="0 0 -0.213"/>
    <parent link="RL_calf"/>
    <child link="RL_foot"/>
  </joint>
  <link name="RL_foot">
    <visual>
      <origin rpy="0 0 0" xyz="0 0 0"/>
      <geometry>
        <sphere radius="0.01"/>
      </geometry>
      <material name="black"/>
    </visual>
    <collision>
      <origin rpy="0 0 0" xyz="0 0 0"/>
      <geometry>
        <sphere radius="0.02"/>
      </geometry>
    </collision>
    <inertial>
      <mass value="0.06"/>
      <inertia ixx="9.6e-06" ixy="0.0" ixz="0.0" iyy="9.6e-06" iyz="0.0" izz="9.6e-06"/>
    </inertial>
  </link>
<!-- ####################################################################################### -->
  <joint name="base_to_torso" type="fixed">
    <parent link="base"/>
    <child link="sagittarius_base_link"/>
    <origin rpy="0 0 0" xyz="0 0 0"/>
  </joint>

  <!-- ####################################################################################### -->
    <link
    name="sagittarius_base_link">
    <inertial>
      <origin
        xyz="0.00793179544277737 2.48115460577673E-19 0.0312047945759253"
        rpy="0 0 0" />
      <mass
        value="0.940146705073746" />
      <inertia
        ixx="0.000950195835062344"
        ixy="3.14825974312405E-20"
        ixz="-0.000200082473207336"
        iyy="0.00267650790326047"
        iyz="-1.01412991222915E-19"
        izz="0.002902663900239" />
    </inertial>
    <visual>
      <origin
        xyz="0 0 0"
        rpy="0 0 0" />
      <geometry>
        <mesh
          filename="../meshes/sagittarius_base_link.STL" />
      </geometry>
      <material
        name="">
        <color
          rgba="1 1 1 1" />
      </material>
    </visual>
    <collision>
      <origin
        xyz="0 0 0"
        rpy="0 0 0" />
      <geometry>
        <mesh
          filename="../meshes/sagittarius_base_link.STL" />
      </geometry>
    </collision>
  </link>
  <link
    name="link1">
    <inertial>
      <origin
        xyz="-7.74579608786574E-10 3.23354786979222E-12 0.0344870497564283"
        rpy="0 0 0" />
      <mass
        value="0.123745079127031" />
      <!-- <mass
        value="0.001" /> -->
      <inertia
        ixx="8.15779591743416E-05"
        ixy="-4.25325094802094E-15"
        ixz="-2.22201794150093E-12"
        iyy="6.7607001964135E-05"
        iyz="-1.59127137655435E-14"
        izz="4.41297902395382E-05" />
    </inertial>
    <visual>
      <origin
        xyz="0 0 0"
        rpy="0 0 0" />
      <geometry>
        <mesh
          filename="../meshes/link1.STL" />
      </geometry>
      <material
        name="">
        <color
          rgba="1 1 1 1" />
      </material>
    </visual>
    <collision>
      <origin
        xyz="0 0 0"
        rpy="0 0 0" />
      <geometry>
        <mesh
          filename="../meshes/link1.STL" />
      </geometry>
    </collision>
  </link>
  <joint
    name="joint_1"
    type="revolute">
    <origin
      xyz="0.045 0 0.07"
      rpy="0 0 0" />
    <parent
      link="sagittarius_base_link" />
    <child
      link="link1" />
    <axis
      xyz="0 0 -1" />
    <limit
      lower="-2"
      upper="2"
      effort="30"
      velocity="30" />
  </joint>
  <link
    name="link2">
    <inertial>
      <origin
        xyz="0.0119015312584793 -1.03639845764692E-08 0.150755903867182"
        rpy="0 0 0" />
      <mass
        value="0.156160822791157" />
      <!-- <mass
        value="0.001" /> -->
      <inertia
        ixx="0.000429266751802994"
        ixy="-2.27426165787001E-11"
        ixz="-5.58862834004722E-05"
        iyy="0.000444676097748043"
        iyz="-2.41993274420629E-10"
        izz="7.916162292894E-05" />
    </inertial>
    <visual>
      <origin
        xyz="0 0 0"
        rpy="0 0 0" />
      <geometry>
        <mesh
          filename="../meshes/link2.STL" />
      </geometry>
      <material
        name="">
        <color
          rgba="0.752941176470588 0.752941176470588 0.752941176470588 1" />
      </material>
    </visual>
    <collision>
      <origin
        xyz="0 0 0"
        rpy="0 0 0" />
      <geometry>
        <mesh
          filename="../meshes/link2.STL" />
      </geometry>
    </collision>
  </link>
  <joint
    name="joint_2"
    type="revolute">
    <origin
      xyz="0 -0.0001 0.055"
      rpy="0 0 0" />
    <parent
      link="link1" />
    <child
      link="link2" />
    <axis
      xyz="0 -1 0" />
    <limit
      lower="-1.57"
      upper="1.4"
      effort="30"
      velocity="30" />
  </joint>
  <link
    name="link3">
    <inertial>
      <origin
        xyz="0.054357321065004 -2.67256405253992E-08 0.00064594073830132"
        rpy="0 0 0" />
      <mass
        value="0.0366487313200473" />
      <!-- <mass
        value="0.001" /> -->
      <inertia
        ixx="9.28701176876329E-06"
        ixy="-2.23878504272996E-11"
        ixz="6.34310578103811E-07"
        iyy="2.0727596617309E-05"
        iyz="-1.71647322080315E-11"
        izz="2.42416271089979E-05" />
    </inertial>
    <visual>
      <origin
        xyz="0 0 0"
        rpy="0 0 0" />
      <geometry>
        <mesh
          filename="../meshes/link3.STL" />
      </geometry>
      <material
        name="">
        <color
          rgba="0.752941176470588 0.752941176470588 0.752941176470588 1" />
      </material>
    </visual>
    <collision>
      <origin
        xyz="0 0 0"
        rpy="0 0 0" />
      <geometry>
        <mesh
          filename="../meshes/link3.STL" />
      </geometry>
    </collision>
  </link>
  <joint
    name="joint_3"
    type="revolute">
    <origin
      xyz="0.033 -0.0001 0.179"
      rpy="0 0 0" />
    <parent
      link="link2" />
    <child
      link="link3" />
    <axis
      xyz="0 -1 0" />
    <limit
      lower="-1.48"
      upper="1.8"
      effort="30"
      velocity="30" />
  </joint>
  <link
    name="link4">
    <inertial>
      <origin
        xyz="0.0444029485674779 -0.00527865310158246 -1.43738021485262E-10"
        rpy="0 0 0" />
      <mass
        value="0.124950088011432" />
      <!-- <mass
        value="0.001" /> -->
      <inertia
        ixx="3.52699895078887E-05"
        ixy="-1.14870103744551E-05"
        ixz="2.45948329713632E-14"
        iyy="0.00010928557067047"
        iyz="-3.42525315676607E-12"
        izz="0.000121451732690361" />
    </inertial>
    <visual>
      <origin
        xyz="0 0 0"
        rpy="0 0 0" />
      <geometry>
        <mesh
          filename="../meshes/link4.STL" />
      </geometry>
      <material
        name="">
        <color
          rgba="0.752941176470588 0.752941176470588 0.752941176470588 1" />
      </material>
    </visual>
    <collision>
      <origin
        xyz="0 0 0"
        rpy="0 0 0" />
      <geometry>
        <mesh
          filename="../meshes/link4.STL" />
      </geometry>
    </collision>
  </link>
  <joint
    name="joint_4"
    type="revolute">
    <origin
      xyz="0.0845 0 0"
      rpy="0 0 0" />
    <parent
      link="link3" />
    <child
      link="link4" />
    <axis
      xyz="-1 0 0" />
    <limit
      lower="-2.90"
      upper="2.90"
      effort="30"
      velocity="30" />
  </joint>
  <link
    name="link5">
    <inertial>
      <origin
        xyz="0.0391172635125616 1.22102848665318E-15 0.011359922796391"
        rpy="0 0 0" />
      <mass
        value="0.0564710099602834" />
      <!-- <mass
        value="0.001" /> -->
      <inertia
        ixx="1.77667699918498E-05"
        ixy="3.77572698012408E-19"
        ixz="-6.79618041712231E-07"
        iyy="1.89643063051294E-05"
        iyz="1.78381670331667E-19"
        izz="1.66130972969903E-05" />
    </inertial>
    <visual>
      <origin
        xyz="0 0 0"
        rpy="0 0 0" />
      <geometry>
        <mesh
          filename="../meshes/link5.STL" />
      </geometry>
      <material
        name="">
        <color
          rgba="0.752941176470588 0.752941176470588 0.752941176470588 1" />
      </material>
    </visual>
    <collision>
      <origin
        xyz="0 0 0"
        rpy="0 0 0" />
      <geometry>
        <mesh
          filename="../meshes/link5.STL" />
      </geometry>
    </collision>
  </link>
  <joint
    name="joint_5"
    type="revolute">
    <origin
      xyz="0.08435 0.00065 0"
      rpy="0 0 0" />
    <parent
      link="link4" />
    <child
      link="link5" />
    <axis
      xyz="0 -1 0" />
    <limit
      lower="-1.8"
      upper="1.60"
      effort="30"
      velocity="30" />
  </joint>
  <link
    name="link6">
    <inertial>
      <origin
        xyz="0.0330748503556987 -1.47583477394259E-10 0.00874151659437283"
        rpy="0 0 0" />
      <mass
        value="0.0790875358325134" />
      <!-- <mass
        value="0.001" /> -->
      <inertia
        ixx="4.00727396068743E-05"
        ixy="1.5026227935429E-13"
        ixz="6.77337873337555E-06"
        iyy="4.37063090227749E-05"
        iyz="-1.73263828329941E-13"
        izz="5.69755186998711E-05" />
    </inertial>
    <visual>
      <origin
        xyz="0 0 0"
        rpy="0 0 0" />
      <geometry>
        <mesh
          filename="../meshes/link6.STL" />
      </geometry>
      <material
        name="">
        <color
          rgba="0.752941176470588 0.752941176470588 0.752941176470588 1" />
      </material>
    </visual>
    <collision>
      <origin
        xyz="0 0 0"
        rpy="0 0 0" />
      <geometry>
        <mesh
          filename="../meshes/link6.STL" />
      </geometry>
    </collision>
  </link>
  <joint
    name="joint_6"
    type="revolute">
    <origin
      xyz="0.061387 0 0"
      rpy="0 0 0" />
    <parent
      link="link5" />
    <child
      link="link6" />
    <axis
      xyz="-1 0 0" />
    <limit
      lower="-3.1"
      upper="3.1"
      effort="30"
      velocity="30" />
  </joint>
  <link
    name="ar_tag_link">
  </link>
  <joint
    name="joint_ar_tag_frame"
    type="fixed">
    <origin
      xyz="0.025 0 0.036"
      rpy="0 0 0" />
    <parent
      link="link6" />
    <child
      link="ar_tag_link" />
    <axis
      xyz="0 0 0" />
    <limit
      lower="0"
      upper="0"
      effort="30"
      velocity="30" />
  </joint>

  <link
    name="link_grasping_frame">
    <inertial>
      <origin
        xyz="-0.29292863789122 -0.000855248417215765 -0.182862893125548"
        rpy="0 0 0" />
      <!-- TODO -->
      <mass
        value="1.55422651132493" />
      <!-- <mass
        value="0.001" /> -->
      <inertia
        ixx="0.0246807389934657"
        ixy="6.12977506319177E-05"
        ixz="-0.0174568851774044"
        iyy="0.0450160124726729"
        iyz="0.000114187269419605"
        izz="0.0218809326193524" />
    </inertial>
  </link>
  <joint
    name="joint_grasping_frame"
    type="fixed">
    <origin
      xyz="0.0557 0 0"
      rpy="0 0 0" />
    <parent
      link="link6" />
    <child
      link="link_grasping_frame" />
    <axis
      xyz="0 0 0" />
    <limit
      lower="0"
      upper="0"
      effort="30"
      velocity="30" />
  </joint>
  <link
    name="link_gripper_left">
    <inertial>
      <origin
        xyz="0.0168448613850675 0.00562743947549268 -3.34157867051821E-05"
        rpy="0 0 0" />
      <mass
        value="0.0185082696416839" />
      <!-- <mass
        value="0.001" /> -->
      <inertia
        ixx="1.65620668352765E-06"
        ixy="3.12039082733024E-07"
        ixz="-1.06123823321138E-09"
        iyy="7.56731403094351E-06"
        iyz="5.54920898904154E-11"
        izz="6.37610666327876E-06" />
    </inertial>
    <visual>
      <origin
        xyz="0 0 0"
        rpy="0 0 0" />
      <geometry>
        <mesh
          filename="../meshes/link_gripper_left.STL" />
      </geometry>
      <material
        name="">
        <color
          rgba="0.752941176470588 0.752941176470588 0.752941176470588 1" />
      </material>
    </visual>
    <collision>
      <origin
        xyz="0 0 0"
        rpy="0 0 0" />
      <geometry>
        <mesh
          filename="../meshes/link_gripper_left.STL" />
      </geometry>
    </collision>
  </link>
  <joint
    name="joint_gripper_left"
    type="prismatic">
    <origin
      xyz="0.0695 0.033 0"
      rpy="0 0 0" />
    <parent
      link="link6" />
    <child
      link="link_gripper_left" />
    <axis
      xyz="0 1 0" />
    <limit
      lower="-0.034"
      upper="0"
      effort="30"
      velocity="30" />
  </joint>
  <link
    name="link_gripper_right">
    <inertial>
      <origin
        xyz="0.0168448612901284 -0.00562743946967042 3.34158424380449E-05"
        rpy="0 0 0" />
      <mass
        value="0.0185082695670405" />
      <!-- <mass
        value="0.001" /> -->
      <inertia
        ixx="1.65620670013429E-06"
        ixy="-3.12039085367371E-07"
        ixz="1.06121397059487E-09"
        iyy="7.56731399585561E-06"
        iyz="5.54960746810554E-11"
        izz="6.37610660879392E-06" />
    </inertial>
    <visual>
      <origin
        xyz="0 0 0"
        rpy="0 0 0" />
      <geometry>
        <mesh
          filename="../meshes/link_gripper_right.STL" />
      </geometry>
      <material
        name="">
        <color
          rgba="0.752941176470588 0.752941176470588 0.752941176470588 1" />
      </material>
    </visual>
    <collision>
      <origin
        xyz="0 0 0"
        rpy="0 0 0" />
      <geometry>
        <mesh
          filename="../meshes/link_gripper_right.STL" />
      </geometry>
    </collision>
  </link>
  <joint
    name="joint_gripper_right"
    type="prismatic">
    <origin
      xyz="0.0695 -0.033 0"
      rpy="0 0 0" />
    <parent
      link="link6" />
    <child
      link="link_gripper_right" />
    <axis
      xyz="0 -1 0" />
    <limit
      lower="-0.034"
      upper="0"
      effort="30"
      velocity="30" />
  </joint>



<!-- ################################################################ -->
  <!-- <link name="ball">
    <visual>
      <origin xyz="0 0 0"/>
      <geometry>
        <sphere radius="0.2"/>
      </geometry>
    </visual>
    <collision>
      <origin xyz="0 0 0"/>
      <geometry>
        <sphere radius="0.2"/>
      </geometry>
    </collision>
    <inertial>
      <mass value="0.5"/>
      <inertia ixx="0.01" ixy="0.0" ixz="0.0" iyy="0.01" iyz="0.0" izz="0.01"/>
    </inertial>
  </link> -->


 </robot>